<!--
Meta Description: # Understanding the "catch" Command in Swift: Error Handling Made Simple ## Synopsis The `catch` keyword in Swift is an essential component of error h...
Meta Keywords: error, catch, you, errors, swift
-->

# Understanding the "catch" Command in Swift: Error Handling Made Simple

## Synopsis
The `catch` keyword in Swift is an essential component of error handling, used in conjunction with `do` and `try` to manage exceptions and ensure robust code execution.

## Documentation
In Swift, errors represent unexpected conditions that can occur during the execution of your code. The `catch` block is part of Swift's error handling mechanism, allowing developers to gracefully handle errors that may arise from functions or methods that can throw.

### Purpose
The primary purpose of the `catch` statement is to provide a way to respond to errors without crashing the application. It allows you to define specific actions to take when an error occurs, ensuring that your code can deal with issues dynamically.

### Usage
The `catch` clause must follow a `do` block that contains the `try` keyword, which indicates that an operation can throw an error. Here’s how the structure typically looks:

```swift
do {
    try someThrowingFunction()
} catch {
    // Handle error
}
```

You can also catch specific error types by matching against them, providing even finer control over error handling.

### Details
- **Multiple Catch Blocks**: You can have multiple `catch` blocks to handle different error types, allowing for tailored responses based on the error.
- **Error Binding**: You can bind errors to a variable in the `catch` block, giving you access to the error details.

Example:

```swift
enum MyError: Error {
    case runtimeError(String)
}

func throwingFunction() throws {
    throw MyError.runtimeError("An error occurred")
}

do {
    try throwingFunction()
} catch MyError.runtimeError(let message) {
    print("Caught runtime error: \(message)")
} catch {
    print("Caught an unexpected error: \(error)")
}
```

## Examples
### Basic Usage
Here’s a simple example demonstrating the use of `catch` in error handling:

```swift
func divide(_ numerator: Int, by denominator: Int) throws -> Int {
    guard denominator != 0 else {
        throw MyError.runtimeError("Division by zero")
    }
    return numerator / denominator
}

do {
    let result = try divide(10, by: 0)
    print("Result: \(result)")
} catch {
    print("Error: \(error)")
}
```

### Catching Specific Errors
You can catch specific errors to tailor your response:

```swift
enum MathError: Error {
    case divisionByZero
}

func safeDivide(_ numerator: Int, by denominator: Int) throws -> Int {
    guard denominator != 0 else {
        throw MathError.divisionByZero
    }
    return numerator / denominator
}

do {
    let result = try safeDivide(10, by: 0)
    print("Result: \(result)")
} catch MathError.divisionByZero {
    print("Error: Cannot divide by zero.")
} catch {
    print("Unexpected error: \(error).")
}
```

## Explanation
### Common Pitfalls
1. **Forgetting the `do` Block**: The `catch` statement must always follow a `do` block. If you omit the `do`, the `catch` will lead to a compilation error.
2. **Ignoring Error Types**: If you catch a general error without handling specific cases, you may overlook critical issues that require distinct handling.
3. **Not Propagating Errors**: If you are in a context where you need to propagate errors, ensure you use `throws` in your function signature.

### Gotchas
- **Unhandled Errors**: Ensure that all potential throwing functions are properly handled in the `do-catch` structure to avoid runtime crashes.
- **Using `try!`**: While `try!` can be used to force a function that throws an error, it will crash your application if an error occurs. It’s generally advisable to use `try` within a `do-catch` block for safer error handling.

## One Line Summary
The `catch` keyword in Swift is integral for managing errors gracefully within a `do` block, allowing developers to respond to exceptions effectively.